2025-07-22 16:29:09,855 - root - INFO - Starting data ingestion process...
2025-07-22 16:29:11,263 - root - INFO - Train set shape: (8844, 32), Test set shape: (2211, 32)
2025-07-22 16:29:11,263 - root - INFO - Train file path: Artifacts\20250722162908\data_ingestion\ingested\train.csv
2025-07-22 16:29:11,302 - root - INFO - Test file path: Artifacts\20250722162908\data_ingestion\ingested\test.csv
2025-07-22 16:29:11,311 - root - INFO - Data ingestion completed successfully.
2025-07-22 16:29:11,314 - root - INFO - Data ingestion completed successfully.
2025-07-22 16:29:11,314 - root - ERROR - Error occurred during data ingestion: Error occurred in file D:\My folder 2025\python for data science\projects\NetworkSecurity\networksecurity\components\data_validatipn.py at line 17: 'DataValidation' object has no attribute 'read_yaml_file'
